Workbook

Sheet data
A1: type | B1: name | C1: site | D1: longitude | E1: latitude | F1: poskey.benthos | G1: poskey.sediment | H1: picture | I1: seagrass.heatwave | J1: sample | K1: seagrass.cover | L1: algae.cover | M1: habitat | N1: seagrassA | O1: seagrassB | P1: seagrass.cover.Laurent | Q1: spectral camera | R1: remark
A2: grid | B2: RG 25 | C2: rewilded | D2: -8.6904504 | E2: 40.672106 | F2: 2025001 | H2: P7150059 | I2: algae | J2: sample | K2: =VLOOKUP(data!H2,cover!$A:$D,3,FALSE) -> + | L2: =VLOOKUP(data!H2,cover!$A:$D,4,FALSE) -> 4 | M2: algae | N2: =VLOOKUP($F2,'seagrass biomass'!$G:$L,2,FALSE) -> 0 | O2: =VLOOKUP($F2,'seagrass biomass'!$G:$L,3,FALSE) -> 0
A3: random | B3: RR 47 | C3: rewilded | D3: -8.6905032 | E3: 40.67236 | F3: 2025002 | H3: P7150061 | I3: no | J3: sample | K3: =VLOOKUP(data!H3,cover!$A:$D,3,FALSE) -> 1 | L3: =VLOOKUP(data!H3,cover!$A:$D,4,FALSE) -> 2 | M3: seagrass | N3: =VLOOKUP($F3,'seagrass biomass'!$G:$L,2,FALSE) -> 0 | O3: =VLOOKUP($F3,'seagrass biomass'!$G:$L,3,FALSE) -> 0
A4: grid | B4: RG 17 | C4: rewilded | D4: -8.6909023 | E4: 40.672397 | F4: 2025003 | H4: P7150062 | I4: no | J4: sample | K4: =VLOOKUP(data!H4,cover!$A:$D,3,FALSE) -> 4 | L4: =VLOOKUP(data!H4,cover!$A:$D,4,FALSE) -> 2 | M4: seagrass | N4: =VLOOKUP($F4,'seagrass biomass'!$G:$L,2,FALSE) -> 315 | O4: =VLOOKUP($F4,'seagrass biomass'!$G:$L,3,FALSE) -> 250
A5: grid | B5: RG 9 | C5: rewilded | D5: -8.6913541 | E5: 40.672687 | F5: 2025004 | H5: P7150063 | I5: no | J5: sample | K5: =VLOOKUP(data!H5,cover!$A:$D,3,FALSE) -> 2 | L5: =VLOOKUP(data!H5,cover!$A:$D,4,FALSE) -> 4 | M5: seagrass | N5: =VLOOKUP($F5,'seagrass biomass'!$G:$L,2,FALSE) -> 42 | O5: =VLOOKUP($F5,'seagrass biomass'!$G:$L,3,FALSE) -> 141
A6: grid | B6: RG 1 | C6: rewilded | D6: -8.691806 | E6: 40.672978 | F6: 2025005 | H6: P7150065 | I6: yes | J6: sample | K6: =VLOOKUP(data!H6,cover!$A:$D,3,FALSE) -> 5 | L6: =VLOOKUP(data!H6,cover!$A:$D,4,FALSE) -> 0 | M6: seagrass | N6: =VLOOKUP($F6,'seagrass biomass'!$G:$L,2,FALSE) -> 2222 | O6: =VLOOKUP($F6,'seagrass biomass'!$G:$L,3,FALSE) -> 939
A7: grid | B7: RG 2 | C7: rewilded | D7: -8.6914241 | E7: 40.673322 | F7: 2025006 | H7: P7150066 | I7: bare | J7: sample | K7: =VLOOKUP(data!H7,cover!$A:$D,3,FALSE) -> 0 | L7: =VLOOKUP(data!H7,cover!$A:$D,4,FALSE) -> 0 | M7: bare | N7: =VLOOKUP($F7,'seagrass biomass'!$G:$L,2,FALSE) -> 17 | O7: =VLOOKUP($F7,'seagrass biomass'!$G:$L,3,FALSE) -> 0
A8: grid | B8: RG 10 | C8: rewilded | D8: -8.6909723 | E8: 40.673031 | F8: 2025007 | H8: P7150067 | I8: algae | J8: sample | K8: =VLOOKUP(data!H8,cover!$A:$D,3,FALSE) -> 0 | L8: =VLOOKUP(data!H8,cover!$A:$D,4,FALSE) -> 5 | M8: algae | N8: =VLOOKUP($F8,'seagrass biomass'!$G:$L,2,FALSE) -> 0 | O8: =VLOOKUP($F8,'seagrass biomass'!$G:$L,3,FALSE) -> 0
A9: random | B9: RR 41 | C9: rewilded | D9: -8.6906446 | E9: 40.672994 | F9: 2025008 | H9: P7150068 | I9: yes | J9: sample | K9: =VLOOKUP(data!H9,cover!$A:$D,3,FALSE) -> 5 | L9: =VLOOKUP(data!H9,cover!$A:$D,4,FALSE) -> 0 | M9: seagrass | N9: =VLOOKUP($F9,'seagrass biomass'!$G:$L,2,FALSE) -> 2418 | O9: =VLOOKUP($F9,'seagrass biomass'!$G:$L,3,FALSE) -> 1706
A10: random | B10: RR 40 | C10: rewilded | D10: -8.6908498 | E10: 40.672778 | F10: 2025009 | H10: P7150069 | I10: yes | J10: sample | K10: =VLOOKUP(data!H10,cover!$A:$D,3,FALSE) -> 5 | L10: =VLOOKUP(data!H10,cover!$A:$D,4,FALSE) -> 0 | M10: seagrass | N10: =VLOOKUP($F10,'seagrass biomass'!$G:$L,2,FALSE) -> 1377 | O10: =VLOOKUP($F10,'seagrass biomass'!$G:$L,3,FALSE) -> 1864
A11: grid | B11: RG 18 | C11: rewilded | D11: -8.6905204 | E11: 40.672741 | F11: 2025010 | H11: P7150070 | I11: yes | J11: sample | K11: =VLOOKUP(data!H11,cover!$A:$D,3,FALSE) -> 5 | L11: =VLOOKUP(data!H11,cover!$A:$D,4,FALSE) -> 0 | M11: seagrass | N11: =VLOOKUP($F11,'seagrass biomass'!$G:$L,2,FALSE) -> 2797 | O11: =VLOOKUP($F11,'seagrass biomass'!$G:$L,3,FALSE) -> 1048
A12: random | B12: RR 48 | C12: rewilded | D12: -8.6902337 | E12: 40.672737 | F12: 2025011 | H12: P7150071 | I12: yes | J12: sample | K12: =VLOOKUP(data!H12,cover!$A:$D,3,FALSE) -> 5 | L12: =VLOOKUP(data!H12,cover!$A:$D,4,FALSE) -> 0 | M12: seagrass | N12: =VLOOKUP($F12,'seagrass biomass'!$G:$L,2,FALSE) -> 3628 | O12: =VLOOKUP($F12,'seagrass biomass'!$G:$L,3,FALSE) -> 977
A13: random | B13: RR 49 | C13: rewilded | D13: -8.6897936 | E13: 40.67296 | F13: 2025012 | H13: P7150072 | I13: bare | J13: sample | K13: =VLOOKUP(data!H13,cover!$A:$D,3,FALSE) -> 0 | L13: =VLOOKUP(data!H13,cover!$A:$D,4,FALSE) -> 0 | M13: bare | N13: =VLOOKUP($F13,'seagrass biomass'!$G:$L,2,FALSE) -> 0 | O13: =VLOOKUP($F13,'seagrass biomass'!$G:$L,3,FALSE) -> 0
... A16: random | B16: RR 34 | C16: rewilded | D16: -8.6906575 | E16: 40.67332 | F16: 2025015 | H16: P7150075 | I16: algae | J16: sample | K16: =VLOOKUP(data!H16,cover!$A:$D,3,FALSE) -> + | L16: =VLOOKUP(data!H16,cover!$A:$D,4,FALSE) -> 4 | M16: algae | N16: =VLOOKUP($F16,'seagrass biomass'!$G:$L,2,FALSE) -> 31 | O16: =VLOOKUP($F16,'seagrass biomass'!$G:$L,3,FALSE) -> 189
A17: grid | B17: RG 3 | C17: rewilded | D17: -8.6910423 | E17: 40.673666 | F17: 2025016 | H17: P7150076 | I17: yes | J17: sample | K17: =VLOOKUP(data!H17,cover!$A:$D,3,FALSE) -> 3 | L17: =VLOOKUP(data!H17,cover!$A:$D,4,FALSE) -> 0 | M17: seagrass | N17: =VLOOKUP($F17,'seagrass biomass'!$G:$L,2,FALSE) -> 977 | O17: =VLOOKUP($F17,'seagrass biomass'!$G:$L,3,FALSE) -> 401 | R17: edge bare and seagrass
A18: grid | B18: RG 4 | C18: rewilded | D18: -8.6906604 | E18: 40.67401 | F18: 2025017 | H18: P7150077 | I18: no | J18: sample | K18: =VLOOKUP(data!H18,cover!$A:$D,3,FALSE) -> 5 | L18: =VLOOKUP(data!H18,cover!$A:$D,4,FALSE) -> + | M18: seagrass | N18: =VLOOKUP($F18,'seagrass biomass'!$G:$L,2,FALSE) -> 994 | O18: =VLOOKUP($F18,'seagrass biomass'!$G:$L,3,FALSE) -> 343
A19: random | B19: RR 35 | C19: rewilded | D19: -8.6905265 | E19: 40.673644 | F19: 2025018 | H19: P7150078 | I19: yes | J19: sample | K19: =VLOOKUP(data!H19,cover!$A:$D,3,FALSE) -> 5 | L19: =VLOOKUP(data!H19,cover!$A:$D,4,FALSE) -> 0 | M19: seagrass | N19: =VLOOKUP($F19,'seagrass biomass'!$G:$L,2,FALSE) -> 2523 | O19: =VLOOKUP($F19,'seagrass biomass'!$G:$L,3,FALSE) -> 1219
A20: grid | B20: RG 12 | C20: rewilded | D20: -8.6902085 | E20: 40.673719 | F20: 2025019 | H20: Laurent | J20: sample | N20: =VLOOKUP($F20,'seagrass biomass'!$G:$L,2,FALSE) -> 2695 | O20: =VLOOKUP($F20,'seagrass biomass'!$G:$L,3,FALSE) -> 1160 | P20: 100 | R20: info spectral cam notes Laurant
A21: grid | B21: RG 21 | C21: rewilded | D21: -8.6893748 | E21: 40.673773 | F21: 2025020 | H21: P7150079 | I21: bare | J21: sample | K21: =VLOOKUP(data!H21,cover!$A:$D,3,FALSE) -> + | L21: =VLOOKUP(data!H21,cover!$A:$D,4,FALSE) -> + | M21: bare | N21: =VLOOKUP($F21,'seagrass biomass'!$G:$L,2,FALSE) -> 0 | O21: =VLOOKUP($F21,'seagrass biomass'!$G:$L,3,FALSE) -> 0
A22: random | B22: RR 43 | C22: rewilded | D22: -8.6895451 | E22: 40.673856 | F22: 2025021 | H22: P7150080 | I22: yes | J22: sample | K22: =VLOOKUP(data!H22,cover!$A:$D,3,FALSE) -> 5 | L22: =VLOOKUP(data!H22,cover!$A:$D,4,FALSE) -> 0 | M22: seagrass | N22: =VLOOKUP($F22,'seagrass biomass'!$G:$L,2,FALSE) -> 933 | O22: =VLOOKUP($F22,'seagrass biomass'!$G:$L,3,FALSE) -> 750
A23: random | B23: RR 44 | C23: rewilded | D23: -8.6896032 | E23: 40.674076 | F23: 2025022 | H23: P7150081 | I23: algae | J23: sample | K23: =VLOOKUP(data!H23,cover!$A:$D,3,FALSE) -> + | L23: =VLOOKUP(data!H23,cover!$A:$D,4,FALSE) -> 5 | M23: algae | N23: =VLOOKUP($F23,'seagrass biomass'!$G:$L,2,FALSE) -> 85 | O23: =VLOOKUP($F23,'seagrass biomass'!$G:$L,3,FALSE) -> 719
A24: grid | B24: RG 13 | C24: rewilded | D24: -8.6898267 | E24: 40.674063 | F24: 2025023 | H24: P7150082 | I24: no | J24: sample | K24: =VLOOKUP(data!H24,cover!$A:$D,3,FALSE) -> 5 | L24: =VLOOKUP(data!H24,cover!$A:$D,4,FALSE) -> 0 | M24: seagrass | N24: =VLOOKUP($F24,'seagrass biomass'!$G:$L,2,FALSE) -> 2790 | O24: =VLOOKUP($F24,'seagrass biomass'!$G:$L,3,FALSE) -> 888 | P24: 100 | Q24: A1-A20
A25: random | B25: RR 36 | C25: rewilded | D25: -8.6902026 | E25: 40.674295 | F25: 2025024 | H25: P7150083 | I25: yes | J25: sample | K25: =VLOOKUP(data!H25,cover!$A:$D,3,FALSE) -> 5 | L25: =VLOOKUP(data!H25,cover!$A:$D,4,FALSE) -> 0 | M25: seagrass | N25: =VLOOKUP($F25,'seagrass biomass'!$G:$L,2,FALSE) -> 2113 | O25: =VLOOKUP($F25,'seagrass biomass'!$G:$L,3,FALSE) -> 675 | P25: 100 | Q25: 20-40
A26: grid | B26: RG 5 | C26: rewilded | D26: -8.6902785 | E26: 40.674354 | F26: 2025025 | H26: P7150084 | I26: yes | J26: sample | K26: =VLOOKUP(data!H26,cover!$A:$D,3,FALSE) -> 5 | L26: =VLOOKUP(data!H26,cover!$A:$D,4,FALSE) -> 0 | M26: seagrass | N26: =VLOOKUP($F26,'seagrass biomass'!$G:$L,2,FALSE) -> 2237 | O26: =VLOOKUP($F26,'seagrass biomass'!$G:$L,3,FALSE) -> 951 | P26: 100 | Q26: 41-60
A27: grid | B27: RG 6 | C27: rewilded | D27: -8.6898967 | E27: 40.674698 | F27: 2025026 | H27: P7150085 | I27: bare | J27: sample | K27: =VLOOKUP(data!H27,cover!$A:$D,3,FALSE) -> 0 | L27: =VLOOKUP(data!H27,cover!$A:$D,4,FALSE) -> 0 | M27: bare | N27: =VLOOKUP($F27,'seagrass biomass'!$G:$L,2,FALSE) -> 0 | O27: =VLOOKUP($F27,'seagrass biomass'!$G:$L,3,FALSE) -> 0 | P27: 0 | Q27: A21-A40
A28: random | B28: RR 37 | C28: rewilded | D28: -8.6895364 | E28: 40.674448 | F28: 2025027 | H28: P7150086 | I28: algae | J28: sample | K28: =VLOOKUP(data!H28,cover!$A:$D,3,FALSE) -> 1 | L28: =VLOOKUP(data!H28,cover!$A:$D,4,FALSE) -> 4 | M28: algae | N28: =VLOOKUP($F28,'seagrass biomass'!$G:$L,2,FALSE) -> 39 | O28: =VLOOKUP($F28,'seagrass biomass'!$G:$L,3,FALSE) -> 161
A29: grid | B29: RG 14 | C29: rewilded | D29: -8.6894448 | E29: 40.674407 | F29: 2025028 | H29: P7150087 | I29: yes | J29: sample | K29: =VLOOKUP(data!H29,cover!$A:$D,3,FALSE) -> 4 | L29: =VLOOKUP(data!H29,cover!$A:$D,4,FALSE) -> + | M29: seagrass | N29: =VLOOKUP($F29,'seagrass biomass'!$G:$L,2,FALSE) -> 2715 | O29: =VLOOKUP($F29,'seagrass biomass'!$G:$L,3,FALSE) -> 1696
A30: random | B30: RR 45 | C30: rewilded | D30: -8.6891629 | E30: 40.674483 | F30: 2025029 | H30: P7150088 | I30: no | J30: sample | K30: =VLOOKUP(data!H30,cover!$A:$D,3,FALSE) -> 2 | L30: =VLOOKUP(data!H30,cover!$A:$D,4,FALSE) -> 0 | M30: seagrass | N30: =VLOOKUP($F30,'seagrass biomass'!$G:$L,2,FALSE) -> 1294 | O30: =VLOOKUP($F30,'seagrass biomass'!$G:$L,3,FALSE) -> 454 | P30: 50 | Q30: A161-A180
A31: grid | B31: RG 22 | C31: rewilded | D31: -8.6889929 | E31: 40.674117 | F31: 2025030 | H31: P7150089 | I31: bare | J31: sample | K31: =VLOOKUP(data!H31,cover!$A:$D,3,FALSE) -> + | L31: =VLOOKUP(data!H31,cover!$A:$D,4,FALSE) -> 0 | M31: bare | N31: =VLOOKUP($F31,'seagrass biomass'!$G:$L,2,FALSE) -> 228 | O31: =VLOOKUP($F31,'seagrass biomass'!$G:$L,3,FALSE) -> 191 | P31: 50 | Q31: A180-A200
A32: random | B32: RR 51 | C32: rewilded | D32: -8.6890769 | E32: 40.673988 | F32: 2025031 | H32: P7150090 | I32: bare | J32: sample | K32: =VLOOKUP(data!H32,cover!$A:$D,3,FALSE) -> 0 | L32: =VLOOKUP(data!H32,cover!$A:$D,4,FALSE) -> + | M32: bare | N32: =VLOOKUP($F32,'seagrass biomass'!$G:$L,2,FALSE) -> 0 | O32: =VLOOKUP($F32,'seagrass biomass'!$G:$L,3,FALSE) -> 0
A33: random | B33: RR 52 | C33: rewilded | D33: -8.6882517 | E33: 40.674107 | F33: 2025032 | H33: P7150091 | I33: bare | J33: sample | K33: =VLOOKUP(data!H33,cover!$A:$D,3,FALSE) -> 0 | L33: =VLOOKUP(data!H33,cover!$A:$D,4,FALSE) -> 0 | M33: bare | N33: =VLOOKUP($F33,'seagrass biomass'!$G:$L,2,FALSE) -> 0 | O33: =VLOOKUP($F33,'seagrass biomass'!$G:$L,3,FALSE) -> 0
A34: grid | B34: RG 31 | C34: rewilded | D34: -8.6881592 | E34: 40.67417 | F34: 2025033 | H34: P7160092 | I34: bare | J34: sample | K34: =VLOOKUP(data!H34,cover!$A:$D,3,FALSE) -> 0 | L34: =VLOOKUP(data!H34,cover!$A:$D,4,FALSE) -> 0 | M34: bare | N34: =VLOOKUP($F34,'seagrass biomass'!$G:$L,2,FALSE) -> 0 | O34: =VLOOKUP($F34,'seagrass biomass'!$G:$L,3,FALSE) -> 0
A35: grid | B35: RG 23 | C35: rewilded | D35: -8.6886111 | E35: 40.674461 | F35: 2025034 | H35: P7160093 | I35: bare | J35: sample | K35: =VLOOKUP(data!H35,cover!$A:$D,3,FALSE) -> 0 | L35: =VLOOKUP(data!H35,cover!$A:$D,4,FALSE) -> 0 | M35: bare | N35: =VLOOKUP($F35,'seagrass biomass'!$G:$L,2,FALSE) -> 0 | O35: =VLOOKUP($F35,'seagrass biomass'!$G:$L,3,FALSE) -> 0 | P35: 0 | Q35: A141-A160
A36: random | B36: RR 46 | C36: rewilded | D36: -8.6887206 | E36: 40.674762 | F36: 2025035 | H36: P7160094 | I36: no | J36: sample | K36: =VLOOKUP(data!H36,cover!$A:$D,3,FALSE) -> 3 | L36: =VLOOKUP(data!H36,cover!$A:$D,4,FALSE) -> 0 | M36: seagrass | N36: =VLOOKUP($F36,'seagrass biomass'!$G:$L,2,FALSE) -> 209 | O36: =VLOOKUP($F36,'seagrass biomass'!$G:$L,3,FALSE) -> 248 | P36: 50 | Q36: A101-A120
A37: grid | B37: RG 16 | C37: rewilded | D37: -8.688681 | E37: 40.675095 | F37: 2025036 | H37: P7160095 | I37: yes | J37: sample | K37: =VLOOKUP(data!H37,cover!$A:$D,3,FALSE) -> 4 | L37: =VLOOKUP(data!H37,cover!$A:$D,4,FALSE) -> 0 | M37: seagrass | N37: =VLOOKUP($F37,'seagrass biomass'!$G:$L,2,FALSE) -> 645 | O37: =VLOOKUP($F37,'seagrass biomass'!$G:$L,3,FALSE) -> 607 | P37: 50 | Q37: A121-A140
A38: grid | B38: RG 15 | C38: rewilded | D38: -8.6890629 | E38: 40.674751 | F38: 2025037 | H38: P7160096 | I38: yes | J38: sample | K38: =VLOOKUP(data!H38,cover!$A:$D,3,FALSE) -> 5 | L38: =VLOOKUP(data!H38,cover!$A:$D,4,FALSE) -> 0 | M38: seagrass | N38: =VLOOKUP($F38,'seagrass biomass'!$G:$L,2,FALSE) -> 1871 | O38: =VLOOKUP($F38,'seagrass biomass'!$G:$L,3,FALSE) -> 1585
A39: random | B39: RR 38 | C39: rewilded | D39: -8.6893755 | E39: 40.674802 | F39: 2025038 | H39: P7160102 | I39: no | J39: sample | K39: =VLOOKUP(data!H39,cover!$A:$D,3,FALSE) -> 4 | L39: =VLOOKUP(data!H39,cover!$A:$D,4,FALSE) -> 0 | M39: seagrass | N39: =VLOOKUP($F39,'seagrass biomass'!$G:$L,2,FALSE) -> 1642 | O39: =VLOOKUP($F39,'seagrass biomass'!$G:$L,3,FALSE) -> 1381
A40: grid | B40: RG 7 | C40: rewilded | D40: -8.6895148 | E40: 40.675042 | F40: 2025039 | H40: P7160103 | I40: bare | J40: sample | K40: =VLOOKUP(data!H40,cover!$A:$D,3,FALSE) -> 0 | L40: =VLOOKUP(data!H40,cover!$A:$D,4,FALSE) -> 0 | M40: bare | N40: =VLOOKUP($F40,'seagrass biomass'!$G:$L,2,FALSE) -> 0 | O40: =VLOOKUP($F40,'seagrass biomass'!$G:$L,3,FALSE) -> 0 | P40: 0 | Q40: A41-A60
A41: grid | B41: RG 8 | C41: rewilded | D41: -8.6891329 | E41: 40.675386 | F41: 2025040 | H41: P7160104 | I41: bare | J41: sample | K41: =VLOOKUP(data!H41,cover!$A:$D,3,FALSE) -> 0 | L41: =VLOOKUP(data!H41,cover!$A:$D,4,FALSE) -> 0 | M41: bare | N41: =VLOOKUP($F41,'seagrass biomass'!$G:$L,2,FALSE) -> 0 | O41: =VLOOKUP($F41,'seagrass biomass'!$G:$L,3,FALSE) -> 0 | P41: 0 | Q41: A61-A50
A42: random | B42: RR 39 | C42: rewilded | D42: -8.6889637 | E42: 40.674983 | F42: 2025081 | H42: P7160112 | I42: yes | J42: sample | K42: =VLOOKUP(data!H42,cover!$A:$D,3,FALSE) -> 5 | L42: =VLOOKUP(data!H42,cover!$A:$D,4,FALSE) -> 0 | M42: seagrass | N42: =VLOOKUP($F42,'seagrass biomass'!$G:$L,2,FALSE) -> 2745 | O42: =VLOOKUP($F42,'seagrass biomass'!$G:$L,3,FALSE) -> 1244
...

Sheet cover
A1: bestand | B1: perc_groen | C1: BB.Seagrass | D1: Algae
A2: P7150059 | B2: 21.091183 | C2: + | D2: 4
A3: P7150061 | B3: 7.0415663 | C3: 1 | D3: 2
A4: P7150062 | B4: 14.091566 | C4: 4 | D4: 2
A5: P7150063 | B5: 6.8943043 | C5: 2 | D5: 4
A6: P7150065 | B6: 10.852686 | C6: 5 | D6: 0
A7: P7150066 | B7: 5.7744062 | C7: 0 | D7: 0
A8: P7150067 | B8: 30.755269 | C8: 0 | D8: 5
A9: P7150068 | B9: 5.8589735 | C9: 5 | D9: 0
A10: P7150069 | B10: 13.129799 | C10: 5 | D10: 0
A11: P7150070 | B11: 20.972158 | C11: 5 | D11: 0
A12: P7150071 | B12: 24.356769 | C12: 5 | D12: 0
A13: P7150072 | B13: 1.6579582 | C13: 0 | D13: 0
A14: P7150073 | B14: 8.5606197 | C14: 5 | D14: 0
A15: P7150074 | B15: 30.626747 | C15: + | D15: 5
A16: P7150075 | B16: 6.6680048 | C16: + | D16: 4
A17: P7150076 | B17: 5.7736022 | C17: 3 | D17: 0
A18: P7150077 | B18: 11.219939 | C18: 5 | D18: +
A19: P7150078 | B19: 15.571298 | C19: 5 | D19: 0
A20: P7150079 | B20: 0.71318724 | C20: + | D20: +
A21: P7150080 | B21: 13.33826 | C21: 5 | D21: 0
A22: P7150081 | B22: 38.429774 | C22: + | D22: 5
A23: P7150082 | B23: 28.680275 | C23: 5 | D23: 0
A24: P7150083 | B24: 16.022306 | C24: 5 | D24: 0
A25: P7150084 | B25: 14.159791 | C25: 5 | D25: 0
A26: P7150085 | B26: 0.72324068 | C26: 0 | D26: 0
A27: P7150086 | B27: 14.648872 | C27: 1 | D27: 4
A28: P7150087 | B28: 7.8148777 | C28: 4 | D28: +
A29: P7150088 | B29: 5.0289909 | C29: 2 | D29: 0
A30: P7150089 | B30: 7.1268171 | C30: + | D30: 0
A31: P7150090 | B31: 2.3120099 | C31: 0 | D31: +
A32: P7150091 | B32: 0.37605195 | C32: 0 | D32: 0
A33: P7160092 | B33: 1.1886217 | C33: 0 | D33: 0
A34: P7160093 | B34: 0.9289482 | C34: 0 | D34: 0
A35: P7160094 | B35: 12.338003 | C35: 3 | D35: 0
A36: P7160095 | B36: 5.2318108 | C36: 4 | D36: 0
A37: P7160096 | B37: 9.2346356 | C37: 5 | D37: 0
A38: P7160102 | B38: 26.038472 | C38: 4 | D38: 0
A39: P7160103 | B39: 0.39706887 | C39: 0 | D39: 0
A40: P7160104 | B40: 1.0713377 | C40: 0 | D40: 0
...

Sheet seagrass biomass
A1: teller | B1: Code | C1: poskey | D1: AB | E1: dry weight (mg) | F1: remark | G1: Gemiddelde van dry weight (mg) | H1: Kolomlabels | S1: Aveiro 07/2025
A2: 1 | B2: 10A | C2: 2025010 | D2: A | E2: 2797 | G2: Rijlabels | H2: A | I2: B | J2: (leeg) | K2: Eindtotaal | L2: totalAB | S2: Oven 48h at 60°C | V2: A = Above ground biomass
A3: 2 | B3: 10B | C3: 2025010 | D3: B | E3: 1048 | G3: 2025003 | H3: 315 | I3: 250 | K3: 282.5 | L3: =H3+I3 -> 565 | V3: B= Belowground biomass
A4: 3 | B4: 113AN | C4: 2025113 | D4: A | E4: 1876 | G4: 2025004 | H4: 42 | I4: 141 | K4: 91.5 | L4: =H4+I4 -> 183 | S4: Code | T4: dry weight (mg)
A5: 4 | B5: 113BN | C5: 2025113 | D5: B | E5: 608 | G5: 2025005 | H5: 2222 | I5: 939 | K5: 1580.5 | L5: =H5+I5 -> 3161 | S5: 10A | T5: 2797 | V5: Seagrass leaves and Roots/Rhizomes
A6: 5 | B6: 115AN | C6: 2025115 | D6: A | E6: 3982 | G6: 2025006 | H6: 17 | I6: 0 | K6: 8.5 | L6: =H6+I6 -> 17 | S6: 10B | T6: 1048
A7: 6 | B7: 115BN | C7: 2025115 | D7: B | E7: 2080 | G7: 2025007 | H7: 0 | I7: 0 | K7: 0 | L7: =H7+I7 -> 0 | S7: 113AN | T7: 1876
A8: 7 | B8: 116AN | C8: 2025116 | D8: A | E8: 3531 | G8: 2025008 | H8: 2418 | I8: 1706 | K8: 2062 | L8: =H8+I8 -> 4124 | S8: 113BN | T8: 608
A9: 8 | B9: 116BN | C9: 2025116 | D9: B | E9: 2364 | G9: 2025009 | H9: 1377 | I9: 1864 | K9: 1620.5 | L9: =H9+I9 -> 3241 | S9: 115AN | T9: 3982
A10: 9 | B10: 117AN | C10: 2025117 | D10: A | E10: 750 | G10: 2025010 | H10: 2797 | I10: 1048 | K10: 1922.5 | L10: =H10+I10 -> 3845 | S10: 115BN | T10: 2080
A11: 10 | B11: 117BN | C11: 2025117 | D11: B | E11: 345 | G11: 2025011 | H11: 3628 | I11: 977 | K11: 2302.5 | L11: =H11+I11 -> 4605 | S11: 116AN | T11: 3531
A12: 11 | B12: 119A | C12: 2025119 | D12: A | E12: 754 | G12: 2025012 | H12: 0 | I12: 0 | K12: 0 | L12: =H12+I12 -> 0 | S12: 116BN | T12: 2364
A13: 12 | B13: 119B | C13: 2025119 | D13: B | E13: 582 | G13: 2025013 | H13: 1701 | I13: 1821 | K13: 1761 | L13: =H13+I13 -> 3522 | S13: 117AN | T13: 750
A14: 13 | B14: 11A | C14: 2025011 | D14: A | E14: 3628 | G14: 2025014 | H14: 0 | I14: 0 | K14: 0 | L14: =H14+I14 -> 0 | S14: 117BN | T14: 345
A15: 14 | B15: 11B | C15: 2025011 | D15: B | E15: 977 | G15: 2025015 | H15: 31 | I15: 189 | K15: 110 | L15: =H15+I15 -> 220 | S15: 119A | T15: 754
A16: 15 | B16: 120AN | C16: 2025120 | D16: A | E16: 12 | G16: 2025016 | H16: 977 | I16: 401 | K16: 689 | L16: =H16+I16 -> 1378 | S16: 119B | T16: 582
A17: 16 | B17: 120BN | C17: 2025120 | D17: B | E17: 118 | G17: 2025017 | H17: 994 | I17: 343 | K17: 668.5 | L17: =H17+I17 -> 1337 | S17: 11A | T17: 3628
... A20: 19 | B20: 122AN | C20: 2025122 | D20: A | E20: 2650 | G20: 2025021 | H20: 933 | I20: 750 | K20: 841.5 | L20: =H20+I20 -> 1683 | S20: 120BN | T20: 118
A21: 20 | B21: 122BN | C21: 2025122 | D21: B | E21: 1147 | G21: 2025022 | H21: 85 | I21: 719 | K21: 402 | L21: =H21+I21 -> 804 | S21: 121AN | T21: empty
A22: 21 | B22: 123AN | C22: 2025123 | D22: A | E22: 0 | G22: 2025023 | H22: 2790 | I22: 888 | K22: 1839 | L22: =H22+I22 -> 3678 | S22: 121BN | T22: empty
A23: 22 | B23: 123BN | C23: 2025123 | D23: B | E23: 0 | G23: 2025024 | H23: 2113 | I23: 675 | K23: 1394 | L23: =H23+I23 -> 2788 | S23: 122AN | T23: 2650
A24: 23 | B24: 124AN | C24: 2025124 | D24: A | E24: 2564 | G24: 2025025 | H24: 2237 | I24: 951 | K24: 1594 | L24: =H24+I24 -> 3188 | S24: 122BN | T24: 1147
A25: 24 | B25: 124BN | C25: 2025124 | D25: B | E25: 2102 | G25: 2025026 | H25: 0 | I25: 0 | K25: 0 | L25: =H25+I25 -> 0 | S25: 123AN | T25: empty
A26: 25 | B26: 125AN | C26: 2025125 | D26: A | E26: 1891 | G26: 2025027 | H26: 39 | I26: 161 | K26: 100 | L26: =H26+I26 -> 200 | S26: 123BN | T26: empty
A27: 26 | B27: 125BN | C27: 2025125 | D27: B | E27: 891 | G27: 2025028 | H27: 2715 | I27: 1696 | K27: 2205.5 | L27: =H27+I27 -> 4411 | S27: 124AN | T27: 2564
A28: 27 | B28: 126AN | C28: 2025126 | D28: A | E28: 2057 | G28: 2025029 | H28: 1294 | I28: 454 | K28: 874 | L28: =H28+I28 -> 1748 | S28: 124BN | T28: 2102
A29: 28 | B29: 126BN | C29: 2025126 | D29: B | E29: 1686 | G29: 2025030 | H29: 228 | I29: 191 | K29: 209.5 | L29: =H29+I29 -> 419 | S29: 125AN | T29: 1891
A30: 29 | B30: 127AN | C30: 2025127 | D30: A | E30: 926 | G30: 2025031 | H30: 0 | I30: 0 | K30: 0 | L30: =H30+I30 -> 0 | S30: 125BN | T30: 891
A31: 30 | B31: 127BN | C31: 2025127 | D31: B | E31: 1187 | G31: 2025034 | H31: 0 | I31: 0 | K31: 0 | L31: =H31+I31 -> 0 | S31: 126AN | T31: 2057
A32: 31 | B32: 128AN | C32: 2025128 | D32: A | E32: 2434 | G32: 2025035 | H32: 209 | I32: 248 | K32: 228.5 | L32: =H32+I32 -> 457 | S32: 126BN | T32: 1686
A33: 32 | B33: 128BN | C33: 2025128 | D33: B | E33: 1076 | G33: 2025036 | H33: 645 | I33: 607 | K33: 626 | L33: =H33+I33 -> 1252 | S33: 127AN | T33: 926
A34: 33 | B34: 12A | C34: 2025012 | D34: A | E34: 0 | G34: 2025037 | H34: 1871 | I34: 1585 | K34: 1728 | L34: =H34+I34 -> 3456 | S34: 127BN | T34: 1187
A35: 34 | B35: 12B | C35: 2025012 | D35: B | E35: 0 | G35: 2025038 | H35: 1642 | I35: 1381 | K35: 1511.5 | L35: =H35+I35 -> 3023 | S35: 128AN | T35: 2434
A36: 35 | B36: 130A | C36: 2025130 | D36: A | E36: 0 | G36: 2025040 | H36: 0 | I36: 0 | K36: 0 | L36: =H36+I36 -> 0 | S36: 128BN | T36: 1076
A37: 36 | B37: 130BN | C37: 2025130 | D37: B | E37: 125 | G37: 2025081 | H37: 2745 | I37: 1244 | K37: 1994.5 | L37: =H37+I37 -> 3989 | S37: 12A | T37: empty
A38: 37 | B38: 132AN | C38: 2025132 | D38: A | E38: 821 | G38: 2025082 | H38: 400 | I38: 338 | K38: 369 | L38: =H38+I38 -> 738 | S38: 12B | T38: empty
A39: 38 | B39: 132BN | C39: 2025132 | D39: B | E39: 561 | G39: 2025084 | H39: 1514 | I39: 556 | K39: 1035 | L39: =H39+I39 -> 2070 | S39: 130A | T39: empty
A40: 39 | B40: 133AN | C40: 2025133 | D40: A | E40: 951 | G40: 2025085 | H40: 2566 | I40: 1512 | K40: 2039 | L40: =H40+I40 -> 4078 | S40: 130BN | T40: 125
A41: 40 | B41: 133BN | C41: 2025133 | D41: B | E41: 578 | G41: 2025086 | H41: 3538 | I41: 2263 | K41: 2900.5 | L41: =H41+I41 -> 5801 | S41: 132AN | T41: 821
A42: 41 | B42: 134AN | C42: 2025134 | D42: A | E42: 12 | G42: 2025087 | H42: 1780 | I42: 1728 | K42: 1754 | L42: =H42+I42 -> 3508 | S42: 132BN | T42: 561
...
